Workbook

Sheet Sheet5
A1: Procure | B1: (Multiple Items)
A2: Status | B2: Not Expired
B3: =SUBTOTAL(9,B5:B58) -> 9916.281 | C3: =SUBTOTAL(9,C5:C57) -> 21859.67 | D3: =SUBTOTAL(9,D5:D57) -> 4864.07 | E3: =SUBTOTAL(9,E5:E57) -> 16995.6 | F3: =SUBTOTAL(9,F5:F57) -> -7289.319
A4: Row Labels | B4: Sum of Balance Qty | C4: Tally Stock | E4: Tally Stock | F4: Diff | G4: Client | H4: Tower No | I4: Balance Qty
A5: ACME Paint Hardtop XP, Part A Black Ral-9005 | B5: 17.39 | C5: 21.91 | D5: 0 | E5: =C5-D5 -> 21.91 | F5: =B5-E5 -> -4.52
A6: ACME Paint Hardtop XP, Part A Perky Blue Ral-5015 | B6: 33.71 | C6: 35.13 | D6: 0 | E6: =C6-D6 -> 35.13 | F6: =B6-E6 -> -1.42
A7: ACME Paint Hardtop XP, Part B Perky Blue Ral-5015 | B7: 3.6 | C7: 5.45 | D7: 0 | E7: =C7-D7 -> 5.45 | F7: =B7-E7 -> -1.85
A8: Ayana Paint Hardtop XP, Part A Hyacinth Blue Ral-2804045 | B8: 49.2 | C8: 52.66 | D8: 0 | E8: =C8-D8 -> 52.66 | F8: =B8-E8 -> -3.46
A9: Ayana Paint Hardtop XP, Part A Oregano Green Ral-1406060 | B9: 32.8 | C9: 36.38 | D9: 0 | E9: =C9-D9 -> 36.38 | F9: =B9-E9 -> -3.58
A10: Ayana Paint Hardtop XP, Part B Hyacinth Blue Ral-2804045 | B10: 5.4 | C10: 0 | D10: 0 | E10: =C10-D10 -> 0 | F10: =B10-E10 -> 5.4
A11: HARDTOP WT8 RAL 7035 A (16.7 Ltr) | B11: 367.4 | C11: 1202.4 | D11: =VLOOKUP(A11,[1]Sheet1!$A$1:$B$16,2,0) -> 167 | E11: =C11-D11 -> 1035.4 | F11: =B11-E11 -> -668
A12: HARDTOP WT8 RAL 7035 B 3.3 Ltr | B12: 69.3 | C12: 250.86 | D12: =VLOOKUP(A12,[1]Sheet1!$A$1:$B$16,2,0) -> 33 | E12: =C12-D12 -> 217.86 | F12: =B12-E12 -> -148.56
A13: Hardtop WT8 RAL 9018 A 16.7 | B13: 751.5 | C13: 317.3 | D13: 0 | E13: =C13-D13 -> 317.3 | F13: =B13-E13 -> 434.2
A14: Hardtop WT8 RAL 9018 B 3.3 | B14: 155.1 | C14: 52.8 | D14: 0 | E14: =C14-D14 -> 52.8 | F14: =B14-E14 -> 102.3
A15: Hardtop XP Comp A RAL 2009 Traffic Orange | B15: 0 | C15: 236.7 | D15: =VLOOKUP(A15,[1]Sheet1!$A$1:$B$16,2,0) -> 67.2 | E15: =C15-D15 -> 169.5 | F15: =B15-E15 -> -169.5
A16: Hardtop XP Comp A RAL 2009 Traffic Orange - 16.807 Ltrs. | B16: 50.421 | C16: 0 | D16: 0 | E16: =C16-D16 -> 0 | F16: =B16-E16 -> 50.421
A17: Hardtop XP Comp A RAL 6029 Mint Green - 18.174 Ltrs. | B17: 18.17 | C17: 0 | D17: 0 | E17: =C17-D17 -> 0 | F17: =B17-E17 -> 18.17
A18: Hardtop XP Comp A RAL9018 | B18: 618.8 | C18: 0 | D18: 0 | E18: =C18-D18 -> 0 | F18: =B18-E18 -> 618.8
A19: Hardtop XP Comp B RAL 2009 Traffic Orange | B19: 5.4 | C19: 23.4 | D19: =VLOOKUP(A19,[1]Sheet1!$A$1:$B$16,2,0) -> 7.2 | E19: =C19-D19 -> 16.2 | F19: =B19-E19 -> -10.8
A20: Hardtop XP Comp B RAL 6029 Mint Green - 1.80 Ltrs. | B20: 1.8 | C20: 0 | D20: 0 | E20: =C20-D20 -> 0 | F20: =B20-E20 -> 1.8
A21: Hardtop XP Comp B RAL 9018 | B21: 54 | C21: 0 | D21: 0 | E21: =C21-D21 -> 0 | F21: =B21-E21 -> 54
A22: Hardtop XP II RAL 9003 Part A 16.02Ltrs. | B22: 320.4 | C22: 1118.72 | D22: =VLOOKUP(A22,[1]Sheet1!$A$1:$B$16,2,0) -> 368.82 | E22: =C22-D22 -> 749.9 | F22: =B22-E22 -> -429.5
A23: Hardtop XP II RAL 9003 Part B 2.2Ltrs. | B23: 41.8 | C23: 151.8 | D23: =VLOOKUP(A23,[1]Sheet1!$A$1:$B$16,2,0) -> 50.6 | E23: =C23-D23 -> 101.2 | F23: =B23-E23 -> -59.4
A24: Hardtop XP RAL 5013 Part A | B24: 17.77 | C24: 17.77 | D24: 0 | E24: =C24-D24 -> 17.77 | F24: =B24-E24 -> 0
A25: Hempaprime Core 500 (47680) 9018 Part - A, Pack Size -16.4Ltrs. | B25: 213.2 | C25: 0 | D25: 0 | E25: =C25-D25 -> 0 | F25: =B25-E25 -> 213.2
A26: Hempaprime Core 500 (47680) 9018 Part - B, Pack Size -3.6Ltrs. | B26: 14.4 | C26: 0 | D26: 0 | E26: =C26-D26 -> 0 | F26: =B26-E26 -> 14.4
A27: Hempaprime Core 500 (47680), Grey Part -A , Pack Size -16.4Ltrs. | B27: 246 | C27: 0 | D27: 0 | E27: =C27-D27 -> 0 | F27: =B27-E27 -> 246
A28: Hempaprime Core 500 (47680), Grey Part -B, Pack Size -3.6Ltrs. | B28: 86.4 | C28: 0 | D28: 0 | E28: =C28-D28 -> 0 | F28: =B28-E28 -> 86.4
A29: Jotun Thinner No.10 | B29: 300 | C29: 1123.4 | D29: =VLOOKUP(A29,[1]Sheet1!$A$1:$B$16,2,0) -> 200 | E29: =C29-D29 -> 923.4 | F29: =B29-E29 -> -623.4
A30: Jotun Thinner No.17 | B30: 735 | C30: 1541.84 | D30: =VLOOKUP(A30,[1]Sheet1!$A$1:$B$16,2,0) -> 440 | E30: =C30-D30 -> 1101.84 | F30: =B30-E30 -> -366.84
A31: Jotun Thinner No-25 | B31: 20 | C31: 0 | D31: 0 | E31: =C31-D31 -> 0 | F31: =B31-E31 -> 20
A32: OC2 JOTUN ZINC 100, B 2.6L | B32: 7.8 | C32: 0 | D32: 0 | E32: =C32-D32 -> 0 | F32: =B32-E32 -> 7.8
A33: Paint Barrier 80 Part A | B33: 262.5 | C33: 237 | D33: =VLOOKUP(A33,[1]Sheet1!$A$1:$B$16,2,0) -> 9 | E33: =C33-D33 -> 228 | F33: =B33-E33 -> 34.5
A34: Paint Barrier 80 Part B | B34: 45 | C34: 38.2 | D34: =VLOOKUP(A34,[1]Sheet1!$A$1:$B$16,2,0) -> 1.25 | E34: =C34-D34 -> 36.95 | F34: =B34-E34 -> 8.05
A35: Paint Penguard Express CF RAL 1013 Part A | B35: 596 | C35: 464 | D35: 0 | E35: =C35-D35 -> 464 | F35: =B35-E35 -> 132
A36: Paint Penguard Express CF RAL 1013 Part B | B36: 64 | C36: 116 | D36: 0 | E36: =C36-D36 -> 116 | F36: =B36-E36 -> -52
A37: Paint Penguard Express RAL 7035 Comp A | B37: 368 | C37: 1261.9 | D37: =VLOOKUP(A37,[1]Sheet1!$A$1:$B$16,2,0) -> 464 | E37: =C37-D37 -> 797.9 | F37: =B37-E37 -> -429.9
A38: Paint Penguard Express RAL 7035 Comp. B | B38: 300 | C38: 334.1 | D38: =VLOOKUP(A38,[1]Sheet1!$A$1:$B$16,2,0) -> 100 | E38: =C38-D38 -> 234.1 | F38: =B38-E38 -> 65.9
A39: Penguard Express Gray Part A (16 Ltr) | B39: 2592 | C39: 8800 | D39: =VLOOKUP(A39,[1]Sheet1!$A$1:$B$16,2,0) -> 2144 | E39: =C39-D39 -> 6656 | F39: =B39-E39 -> -4064
A40: Penguard Express Grey Part B (4 Ltr) | B40: 412 | C40: 2176 | D40: =VLOOKUP(A40,[1]Sheet1!$A$1:$B$16,2,0) -> 552 | E40: =C40-D40 -> 1624 | F40: =B40-E40 -> -1212
...

Sheet Sheet1
D2: 45852 | E2: 14/7 OLD | I2: =SUBTOTAL(9,I4:I56) -> 1371.51 | L2: 45897
B3: Items | C3: Sum of Balance Qty | D3: Issuance as per TALLY | E3: Tally Stock | I3: Diff | J3: Balance | K3: Tally | L3: Issuance as per TALLY | M3: Diff | R3: Diff
B4: ACME Paint Hardtop XP, Part A Black Ral-9005 | C4: 17.39 | D4: 21.91 | E4: 21.91 | F4: =D4=E4 -> TRUE | G4: =VLOOKUP(B4,Sheet5!$A4:$C60,3,0) -> 21.91 | H4: =D4-G4 -> 0 | I4: -4.52 | J4: =VLOOKUP(B4,Sheet5!A5:B57,2,0) -> 17.39 | K4: =VLOOKUP(B4,[2]Sheet2!$A:$F,6,0) -> 21.91 | L4: =K4 -> 21.91 | M4: =K4-J4 -> 4.52 | N4: =M4+I4 -> 0 | P4: =E4-K4 -> 0 | R4: =L4-D4 -> 0
B5: ACME Paint Hardtop XP, Part A Perky Blue Ral-5015 | C5: 33.71 | D5: =E5 -> 35.13 | E5: 35.13 | F5: =D5=E5 -> TRUE | G5: =VLOOKUP(B5,Sheet5!$A5:$C61,3,0) -> 35.13 | H5: =D5-G5 -> 0 | I5: -1.42 | J5: =VLOOKUP(B5,Sheet5!A6:B58,2,0) -> 33.71 | K5: =VLOOKUP(B5,[2]Sheet2!$A:$F,6,0) -> 35.13 | L5: =K5 -> 35.13 | M5: =K5-J5 -> 1.42 | N5: =M5+I5 -> 0 | P5: =E5-K5 -> 0 | R5: =L5-D5 -> 0
B6: ACME Paint Hardtop XP, Part B Perky Blue Ral-5015 | C6: 3.6 | D6: =E6 -> 5.45 | E6: 5.45 | F6: =D6=E6 -> TRUE | G6: =VLOOKUP(B6,Sheet5!$A6:$C62,3,0) -> 5.45 | H6: =D6-G6 -> 0 | I6: -1.85 | J6: =VLOOKUP(B6,Sheet5!A7:B59,2,0) -> 3.6 | K6: =VLOOKUP(B6,[2]Sheet2!$A:$F,6,0) -> 5.45 | L6: =K6 -> 5.45 | M6: =K6-J6 -> 1.85 | N6: =M6+I6 -> 0 | P6: =E6-K6 -> 0 | R6: =L6-D6 -> 0
B7: Ayana Paint Hardtop XP, Part A Hyacinth Blue Ral-2804045 | C7: 49.2 | D7: =VLOOKUP(B7,[3]Sheet1!$A:$B,2,0) -> 52.66 | E7: 52.66 | F7: =D7=E7 -> TRUE | G7: =VLOOKUP(B7,Sheet5!$A7:$C63,3,0) -> 52.66 | H7: =D7-G7 -> 0 | I7: -3.46 | J7: =VLOOKUP(B7,Sheet5!A8:B60,2,0) -> 49.2 | K7: =VLOOKUP(B7,[2]Sheet2!$A:$F,6,0) -> 52.66 | L7: =VLOOKUP(B7,[4]Sheet1!$A:$B,2,0) -> 52.66 | M7: =K7-J7 -> 3.46 | N7: =M7+I7 -> 0 | P7: =E7-K7 -> 0 | R7: =L7-D7 -> 0
B8: Ayana Paint Hardtop XP, Part A Oregano Green Ral-1406060 | C8: 32.8 | D8: =VLOOKUP(B8,[3]Sheet1!$A:$B,2,0) -> 36.38 | E8: 36.38 | F8: =D8=E8 -> TRUE | G8: =VLOOKUP(B8,Sheet5!$A8:$C64,3,0) -> 36.38 | H8: =D8-G8 -> 0 | I8: -3.58 | J8: =VLOOKUP(B8,Sheet5!A9:B61,2,0) -> 32.8 | K8: =VLOOKUP(B8,[2]Sheet2!$A:$F,6,0) -> 36.38 | L8: =VLOOKUP(B8,[4]Sheet1!$A:$B,2,0) -> 36.38 | M8: =K8-J8 -> 3.58 | N8: =M8+I8 -> 0 | P8: =E8-K8 -> 0 | R8: =L8-D8 -> 0
B9: Ayana Paint Hardtop XP, Part B Hyacinth Blue Ral-2804045 | C9: 5.4 | D9: 0 | E9: 0 | F9: =D9=E9 -> TRUE | G9: =VLOOKUP(B9,Sheet5!$A9:$C65,3,0) -> 0 | H9: =D9-G9 -> 0 | I9: 5.4 | J9: =VLOOKUP(B9,Sheet5!A10:B62,2,0) -> 5.4 | K9: 0 | L9: 0 | M9: =K9-J9 -> -5.4 | N9: =M9+I9 -> 0 | P9: =E9-K9 -> 0 | R9: =L9-D9 -> 0
B10: HARDTOP WT8 RAL 7035 A (16.7 Ltr) | C10: 918.5 | D10: =VLOOKUP(B10,[3]Sheet1!$A:$B,2,0) -> 1202.4 | E10: 1035.4 | F10: =D10=E10 -> FALSE | G10: =VLOOKUP(B10,Sheet5!$A10:$C66,3,0) -> 1202.4 | H10: =D10-G10 -> 0 | I10: -116.9 | J10: =VLOOKUP(B10,Sheet5!A11:B63,2,0) -> 367.4 | K10: =VLOOKUP(B10,[2]Sheet2!$A:$F,6,0) -> 517.7 | L10: =VLOOKUP(B10,[4]Sheet1!$A:$B,2,0) -> 434.2 | M10: =K10-J10 -> 150.3 | N10: =M10+I10 -> 33.4 | O10: =N10/16.7 -> 2 | P10: =E10-K10 -> 517.7 | R10: =D10-L10 -> 768.2
B11: HARDTOP WT8 RAL 7035 B 3.3 Ltr | C11: 178.2 | D11: =VLOOKUP(B11,[3]Sheet1!$A:$B,2,0) -> 250.86 | E11: 217.86 | F11: =D11=E11 -> FALSE | G11: =VLOOKUP(B11,Sheet5!$A11:$C67,3,0) -> 250.86 | H11: =D11-G11 -> 0 | I11: -39.66 | J11: =VLOOKUP(B11,Sheet5!A12:B64,2,0) -> 69.3 | K11: =VLOOKUP(B11,[2]Sheet2!$A:$F,6,0) -> 115.56 | L11: =VLOOKUP(B11,[4]Sheet1!$A:$B,2,0) -> 99.06 | M11: =K11-J11 -> 46.26 | N11: =M11+I11 -> 6.6 | O11: =N11/3.3 -> 2 | P11: =E11-K11 -> 102.3 | R11: =D11-L11 -> 151.8
B12: Hardtop WT8 RAL 9018 A 16.7 | C12: 835 | D12: =VLOOKUP(B12,[3]Sheet1!$A:$B,2,0) -> 317.3 | E12: 317.3 | F12: =D12=E12 -> TRUE | G12: =VLOOKUP(B12,Sheet5!$A12:$C68,3,0) -> 317.3 | H12: =D12-G12 -> 0 | I12: 517.7 | J12: =VLOOKUP(B12,Sheet5!A13:B65,2,0) -> 751.5 | K12: =VLOOKUP(B12,[2]Sheet2!$A:$F,6,0) -> 233.8 | L12: =VLOOKUP(B12,[4]Sheet1!$A:$B,2,0) -> 233.8 | M12: =K12-J12 -> -517.7 | N12: =M12+I12 -> 0 | P12: =E12-K12 -> 83.5 | R12: =D12-L12 -> 83.5
B13: Hardtop WT8 RAL 9018 B 3.3 | C13: 171.6 | D13: =VLOOKUP(B13,[3]Sheet1!$A:$B,2,0) -> 52.8 | E13: 52.8 | F13: =D13=E13 -> TRUE | G13: =VLOOKUP(B13,Sheet5!$A13:$C69,3,0) -> 52.8 | H13: =D13-G13 -> 0 | I13: 118.8 | J13: =VLOOKUP(B13,Sheet5!A14:B66,2,0) -> 155.1 | K13: =VLOOKUP(B13,[2]Sheet2!$A:$F,6,0) -> 36.3 | L13: =VLOOKUP(B13,[4]Sheet1!$A:$B,2,0) -> 36.3 | M13: =K13-J13 -> -118.8 | N13: =M13+I13 -> 0 | P13: =E13-K13 -> 16.5 | R13: =D13-L13 -> 16.5
B14: Hardtop XP Comp A RAL 2009 Traffic Orange | C14: 117.67 | D14: =VLOOKUP(B14,[3]Sheet1!$A:$B,2,0) -> 236.7 | E14: 169.5 | F14: =D14=E14 -> FALSE | G14: =VLOOKUP(B14,Sheet5!$A14:$C70,3,0) -> 236.7 | H14: =D14-G14 -> 0 | I14: -51.83 | J14: =VLOOKUP(B14,Sheet5!A15:B67,2,0) -> 0 | K14: =VLOOKUP(B14,[2]Sheet2!$A:$F,6,0) -> 51.9 | L14: =VLOOKUP(B14,[4]Sheet1!$A:$B,2,0) -> 35.1 | M14: =K14-J14 -> 51.9 | N14: =M14+I14 -> 0.07 | P14: =E14-K14 -> 117.6 | R14: =D14-L14 -> 201.6
B15: Hardtop XP Comp A RAL 2009 Traffic Orange - 16.807 Ltrs. | C15: 50.421 | D15: 0 | E15: 0 | F15: =D15=E15 -> TRUE | G15: =VLOOKUP(B15,Sheet5!$A15:$C71,3,0) -> 0 | H15: =D15-G15 -> 0 | I15: 50.421 | J15: =VLOOKUP(B15,Sheet5!A16:B68,2,0) -> 50.421 | K15: 0 | L15: 0 | M15: =K15-J15 -> -50.421 | N15: =M15+I15 -> 0 | P15: =E15-K15 -> 0 | R15: =L15-D15 -> 0
B16: Hardtop XP Comp A RAL 6029 Mint Green - 18.174 Ltrs. | C16: 18.17 | D16: 0 | E16: 0 | F16: =D16=E16 -> TRUE | G16: =VLOOKUP(B16,Sheet5!$A16:$C72,3,0) -> 0 | H16: =D16-G16 -> 0 | I16: 18.17 | J16: =VLOOKUP(B16,Sheet5!A17:B69,2,0) -> 18.17 | K16: 0 | L16: 0 | M16: =K16-J16 -> -18.17 | N16: =M16+I16 -> 0 | P16: =E16-K16 -> 0 | R16: =L16-D16 -> 0
B17: Hardtop XP Comp A RAL9018 | C17: 618.8 | D17: 0 | E17: 0 | F17: =D17=E17 -> TRUE | G17: =VLOOKUP(B17,Sheet5!$A17:$C73,3,0) -> 0 | H17: =D17-G17 -> 0 | I17: 618.8 | J17: =VLOOKUP(B17,Sheet5!A18:B70,2,0) -> 618.8 | K17: 0 | L17: 0 | M17: =K17-J17 -> -618.8 | N17: =M17+I17 -> 0 | P17: =E17-K17 -> 0 | R17: =L17-D17 -> 0
B18: Hardtop XP Comp B RAL 2009 Traffic Orange | C18: 18 | D18: =VLOOKUP(B18,[3]Sheet1!$A:$B,2,0) -> 23.4 | E18: 16.2 | F18: =D18=E18 -> FALSE | G18: =VLOOKUP(B18,Sheet5!$A18:$C74,3,0) -> 23.4 | H18: =D18-G18 -> 0 | I18: 1.8 | J18: =VLOOKUP(B18,Sheet5!A19:B71,2,0) -> 5.4 | K18: =VLOOKUP(B18,[2]Sheet2!$A:$F,6,0) -> 3.6 | L18: =VLOOKUP(B18,[4]Sheet1!$A:$B,2,0) -> 1.8 | M18: =K18-J18 -> -1.8 | N18: =M18+I18 -> 0 | P18: =E18-K18 -> 12.6 | R18: =D18-L18 -> 21.6
B19: Hardtop XP Comp B RAL 6029 Mint Green - 1.80 Ltrs. | C19: 1.8 | D19: 0 | E19: 0 | F19: =D19=E19 -> TRUE | G19: =VLOOKUP(B19,Sheet5!$A19:$C75,3,0) -> 0 | H19: =D19-G19 -> 0 | I19: 1.8 | J19: =VLOOKUP(B19,Sheet5!A20:B72,2,0) -> 1.8 | K19: 0 | L19: 0 | M19: =K19-J19 -> -1.8 | N19: =M19+I19 -> 0 | P19: =E19-K19 -> 0 | R19: =L19-D19 -> 0
B20: Hardtop XP Comp B RAL 9018 | C20: 54 | D20: 0 | E20: 0 | F20: =D20=E20 -> TRUE | G20: =VLOOKUP(B20,Sheet5!$A20:$C76,3,0) -> 0 | H20: =D20-G20 -> 0 | I20: 54 | J20: =VLOOKUP(B20,Sheet5!A21:B73,2,0) -> 54 | K20: 0 | L20: 0 | M20: =K20-J20 -> -54 | N20: =M20+I20 -> 0 | P20: =E20-K20 -> 0 | R20: =L20-D20 -> 0
B21: Hardtop XP II RAL 9003 Part A 16.02Ltrs. | C21: 752.94 | D21: =VLOOKUP(B21,[3]Sheet1!$A:$B,2,0) -> 1118.72 | E21: 749.9 | F21: =D21=E21 -> FALSE | G21: =VLOOKUP(B21,Sheet5!$A21:$C77,3,0) -> 1118.72 | H21: =D21-G21 -> 0 | I21: 3.04 | J21: =VLOOKUP(B21,Sheet5!A22:B74,2,0) -> 320.4 | K21: =VLOOKUP(B21,[2]Sheet2!$A:$F,6,0) -> 315.56 | L21: =VLOOKUP(B21,[4]Sheet1!$A:$B,2,0) -> 315.56 | M21: =K21-J21 -> -4.84 | N21: =M21+I21 -> -1.8 | P21: =E21-K21 -> 434.34 | R21: =D21-L21 -> 803.16
B22: Hardtop XP II RAL 9003 Part B 2.2Ltrs. | C22: 101.2 | D22: =VLOOKUP(B22,[3]Sheet1!$A:$B,2,0) -> 151.8 | E22: 101.2 | F22: =D22=E22 -> FALSE | G22: =VLOOKUP(B22,Sheet5!$A22:$C78,3,0) -> 151.8 | H22: =D22-G22 -> 0 | I22: 0 | J22: =VLOOKUP(B22,Sheet5!A23:B75,2,0) -> 41.8 | K22: =VLOOKUP(B22,[2]Sheet2!$A:$F,6,0) -> 41.8 | L22: =VLOOKUP(B22,[4]Sheet1!$A:$B,2,0) -> 41.8 | M22: =K22-J22 -> 0 | N22: =M22+I22 -> 0 | P22: =E22-K22 -> 59.4 | R22: =D22-L22 -> 110
B23: Hardtop XP RAL 5013 Part A | C23: 17.77 | D23: =VLOOKUP(B23,[3]Sheet1!$A:$B,2,0) -> 17.77 | E23: 17.77 | F23: =D23=E23 -> TRUE | G23: =VLOOKUP(B23,Sheet5!$A23:$C79,3,0) -> 17.77 | H23: =D23-G23 -> 0 | I23: 0 | J23: =VLOOKUP(B23,Sheet5!A24:B76,2,0) -> 17.77 | K23: =VLOOKUP(B23,[2]Sheet2!$A:$F,6,0) -> 17.77 | L23: =VLOOKUP(B23,[4]Sheet1!$A:$B,2,0) -> 17.77 | M23: =K23-J23 -> 0 | N23: =M23+I23 -> 0 | P23: =E23-K23 -> 0 | R23: =L23-D23 -> 0
B24: Hempaprime Core 500 (47680) 9018 Part - A, Pack Size -16.4Ltrs. | C24: 213.2 | D24: 0 | E24: 0 | F24: =D24=E24 -> TRUE | G24: =VLOOKUP(B24,Sheet5!$A24:$C80,3,0) -> 0 | H24: =D24-G24 -> 0 | I24: 213.2 | J24: =VLOOKUP(B24,Sheet5!A25:B77,2,0) -> 213.2 | K24: 0 | L24: 0 | M24: =K24-J24 -> -213.2 | N24: =M24+I24 -> 0 | P24: =E24-K24 -> 0 | R24: =L24-D24 -> 0
B25: Hempaprime Core 500 (47680) 9018 Part - B, Pack Size -3.6Ltrs. | C25: 14.4 | D25: 0 | E25: 0 | F25: =D25=E25 -> TRUE | G25: =VLOOKUP(B25,Sheet5!$A25:$C81,3,0) -> 0 | H25: =D25-G25 -> 0 | I25: 14.4 | J25: =VLOOKUP(B25,Sheet5!A26:B78,2,0) -> 14.4 | K25: 0 | L25: 0 | M25: =K25-J25 -> -14.4 | N25: =M25+I25 -> 0 | P25: =E25-K25 -> 0 | R25: =L25-D25 -> 0
B26: Hempaprime Core 500 (47680), Grey Part -A , Pack Size -16.4Ltrs. | C26: 246 | D26: 0 | E26: 0 | F26: =D26=E26 -> TRUE | G26: =VLOOKUP(B26,Sheet5!$A26:$C82,3,0) -> 0 | H26: =D26-G26 -> 0 | I26: 246 | J26: =VLOOKUP(B26,Sheet5!A27:B79,2,0) -> 246 | K26: 0 | L26: 0 | M26: =K26-J26 -> -246 | N26: =M26+I26 -> 0 | P26: =E26-K26 -> 0 | R26: =L26-D26 -> 0
B27: Hempaprime Core 500 (47680), Grey Part -B, Pack Size -3.6Ltrs. | C27: 86.4 | D27: 0 | E27: 0 | F27: =D27=E27 -> TRUE | G27: =VLOOKUP(B27,Sheet5!$A27:$C83,3,0) -> 0 | H27: =D27-G27 -> 0 | I27: 86.4 | J27: =VLOOKUP(B27,Sheet5!A28:B80,2,0) -> 86.4 | K27: 0 | L27: 0 | M27: =K27-J27 -> -86.4 | N27: =M27+I27 -> 0 | P27: =E27-K27 -> 0 | R27: =L27-D27 -> 0
B28: Jotun Thinner No.10 | C28: 820 | D28: =VLOOKUP(B28,[3]Sheet1!$A:$B,2,0) -> 1110 | E28: 923.4 | F28: =D28=E28 -> FALSE | G28: =VLOOKUP(B28,Sheet5!$A28:$C84,3,0) -> 1123.4 | H28: =D28-G28 -> -13.4 | I28: -103.4 | J28: =VLOOKUP(B28,Sheet5!A29:B81,2,0) -> 300 | K28: =VLOOKUP(B28,[2]Sheet2!$A:$F,6,0) -> 430 | L28: =VLOOKUP(B28,[4]Sheet1!$A:$B,2,0) -> 390 | M28: =K28-J28 -> 130 | N28: =M28+I28 -> 26.6 | P28: =E28-K28 -> 493.4 | R28: =D28-L28 -> 720
B29: Jotun Thinner No.17 | C29: 1575 | D29: =VLOOKUP(B29,[3]Sheet1!$A:$B,2,0) -> 1569.9 | E29: 1101.84 | F29: =D29=E29 -> FALSE | G29: =VLOOKUP(B29,Sheet5!$A29:$C85,3,0) -> 1541.84 | H29: =D29-G29 -> 28.06 | I29: 473.16 | J29: =VLOOKUP(B29,Sheet5!A30:B82,2,0) -> 735 | K29: =VLOOKUP(B29,[2]Sheet2!$A:$F,6,0) -> 229.9 | L29: =VLOOKUP(B29,[4]Sheet1!$A:$B,2,0) -> 169.9 | M29: =K29-J29 -> -505.1 | N29: =M29+I29 -> -31.94 | P29: =E29-K29 -> 871.94 | R29: =D29-L29 -> 1400
B30: Jotun Thinner No-25 | C30: 20 | D30: 0 | E30: 0 | F30: =D30=E30 -> TRUE | G30: =VLOOKUP(B30,Sheet5!$A30:$C86,3,0) -> 0 | H30: =D30-G30 -> 0 | I30: 20 | J30: =VLOOKUP(B30,Sheet5!A31:B83,2,0) -> 20 | K30: 0 | L30: 0 | M30: =K30-J30 -> -20 | N30: =M30+I30 -> 0 | P30: =E30-K30 -> 0 | R30: =L30-D30 -> 0
B31: OC2 JOTUN ZINC 100, B 2.6L | C31: 7.8 | D31: 0 | E31: 0 | F31: =D31=E31 -> TRUE | G31: =VLOOKUP(B31,Sheet5!$A31:$C87,3,0) -> 0 | H31: =D31-G31 -> 0 | I31: 7.8 | J31: =VLOOKUP(B31,Sheet5!A32:B84,2,0) -> 7.8 | K31: 0 | L31: 0 | M31: =K31-J31 -> -7.8 | N31: =M31+I31 -> 0 | P31: =E31-K31 -> 0 | R31: =L31-D31 -> 0
B32: Paint Barrier 80 Part A | C32: 285 | D32: =VLOOKUP(B32,[3]Sheet1!$A:$B,2,0) -> 237 | E32: 228 | F32: =D32=E32 -> FALSE | G32: =VLOOKUP(B32,Sheet5!$A32:$C88,3,0) -> 237 | H32: =D32-G32 -> 0 | I32: 57 | J32: =VLOOKUP(B32,Sheet5!A33:B85,2,0) -> 262.5 | K32: =VLOOKUP(B32,[2]Sheet2!$A:$F,6,0) -> 205.5 | L32: =VLOOKUP(B32,[4]Sheet1!$A:$B,2,0) -> 205.5 | M32: =K32-J32 -> -57 | N32: =M32+I32 -> 0 | P32: =E32-K32 -> 22.5 | R32: =D32-L32 -> 31.5
B33: Paint Barrier 80 Part B | C33: 48.75 | D33: =VLOOKUP(B33,[3]Sheet1!$A:$B,2,0) -> 38.2 | E33: 36.95 | F33: =D33=E33 -> FALSE | G33: =VLOOKUP(B33,Sheet5!$A33:$C89,3,0) -> 38.2 | H33: =D33-G33 -> 0 | I33: 11.8 | J33: =VLOOKUP(B33,Sheet5!A34:B86,2,0) -> 45 | K33: =VLOOKUP(B33,[2]Sheet2!$A:$F,6,0) -> 33.2 | L33: =VLOOKUP(B33,[4]Sheet1!$A:$B,2,0) -> 33.2 | M33: =K33-J33 -> -11.8 | N33: =M33+I33 -> 0 | P33: =E33-K33 -> 3.75 | R33: =D33-L33 -> 5
B34: Paint Penguard Express CF RAL 1013 Part A | C34: 672 | D34: =VLOOKUP(B34,[3]Sheet1!$A:$B,2,0) -> 464 | E34: 464 | F34: =D34=E34 -> TRUE | G34: =VLOOKUP(B34,Sheet5!$A34:$C90,3,0) -> 464 | H34: =D34-G34 -> 0 | I34: 208 | J34: =VLOOKUP(B34,Sheet5!A35:B87,2,0) -> 596 | K34: =VLOOKUP(B34,[2]Sheet2!$A:$F,6,0) -> 352 | L34: =VLOOKUP(B34,[4]Sheet1!$A:$B,2,0) -> 352 | M34: =K34-J34 -> -244 | N34: =M34+I34 -> -36 | O34: =N34/16 -> -2.25 | P34: =E34-K34 -> 112 | R34: =D34-L34 -> 112
B35: Paint Penguard Express CF RAL 1013 Part B | C35: 92 | D35: =VLOOKUP(B35,[3]Sheet1!$A:$B,2,0) -> 116 | E35: 116 | F35: =D35=E35 -> TRUE | G35: =VLOOKUP(B35,Sheet5!$A35:$C91,3,0) -> 116 | H35: =D35-G35 -> 0 | I35: -24 | J35: =VLOOKUP(B35,Sheet5!A36:B88,2,0) -> 64 | K35: =VLOOKUP(B35,[2]Sheet2!$A:$F,6,0) -> 88 | L35: =VLOOKUP(B35,[4]Sheet1!$A:$B,2,0) -> 88 | M35: =K35-J35 -> 24 | N35: =M35+I35 -> 0 | P35: =E35-K35 -> 28 | R35: =D35-L35 -> 28
B36: Paint Penguard Express RAL 7035 Comp A | C36: 848 | D36: =VLOOKUP(B36,[3]Sheet1!$A:$B,2,0) -> 1261.9 | E36: 797.9 | F36: =D36=E36 -> FALSE | G36: =VLOOKUP(B36,Sheet5!$A36:$C92,3,0) -> 1261.9 | H36: =D36-G36 -> 0 | I36: 50.1 | J36: =VLOOKUP(B36,Sheet5!A37:B89,2,0) -> 368 | K36: =VLOOKUP(B36,[2]Sheet2!$A:$F,6,0) -> 269.9 | L36: =VLOOKUP(B36,[4]Sheet1!$A:$B,2,0) -> 269.9 | M36: =K36-J36 -> -98.1 | N36: =M36+I36 -> -48 | P36: =E36-K36 -> 528 | R36: =D36-L36 -> 992
B37: Paint Penguard Express RAL 7035 Comp. B | C37: 460 | D37: =VLOOKUP(B37,[3]Sheet1!$A:$B,2,0) -> 334.1 | E37: 234.1 | F37: =D37=E37 -> FALSE | G37: =VLOOKUP(B37,Sheet5!$A37:$C93,3,0) -> 334.1 | H37: =D37-G37 -> 0 | I37: 225.9 | J37: =VLOOKUP(B37,Sheet5!A38:B90,2,0) -> 300 | K37: =VLOOKUP(B37,[2]Sheet2!$A:$F,6,0) -> 102.1 | L37: =VLOOKUP(B37,[4]Sheet1!$A:$B,2,0) -> 102.1 | M37: =K37-J37 -> -197.9 | N37: =M37+I37 -> 28 | P37: =E37-K37 -> 132 | R37: =D37-L37 -> 232
B38: Penguard Express Gray Part A (16 Ltr) | C38: 6896 | D38: =VLOOKUP(B38,[3]Sheet1!$A:$B,2,0) -> 8800 | E38: 6656 | F38: =D38=E38 -> FALSE | G38: =VLOOKUP(B38,Sheet5!$A38:$C94,3,0) -> 8800 | H38: =D38-G38 -> 0 | I38: 240 | J38: =VLOOKUP(B38,Sheet5!A39:B91,2,0) -> 2592 | K38: =VLOOKUP(B38,[2]Sheet2!$A:$F,6,0) -> 2544 | L38: =VLOOKUP(B38,[4]Sheet1!$A:$B,2,0) -> 2208 | M38: =K38-J38 -> -48 | N38: =M38+I38 -> 192 | O38: =N38/16 -> 12 | P38: =E38-K38 -> 4112 | R38: =D38-L38 -> 6592
B39: Penguard Express Grey Part B (4 Ltr) | C39: 1568 | D39: =VLOOKUP(B39,[3]Sheet1!$A:$B,2,0) -> 2176 | E39: 1624 | F39: =D39=E39 -> FALSE | G39: =VLOOKUP(B39,Sheet5!$A39:$C95,3,0) -> 2176 | H39: =D39-G39 -> 0 | I39: -56 | J39: =VLOOKUP(B39,Sheet5!A40:B92,2,0) -> 412 | K39: =VLOOKUP(B39,[2]Sheet2!$A:$F,6,0) -> 596 | L39: =VLOOKUP(B39,[4]Sheet1!$A:$B,2,0) -> 512 | M39: =K39-J39 -> 184 | N39: =M39+I39 -> 128 | O39: =N39/4 -> 32 | P39: =E39-K39 -> 1028 | R39: =D39-L39 -> 1664
B40: Penguard Express Ral 9018 (Part A) | C40: 928 | D40: =VLOOKUP(B40,[3]Sheet1!$A:$B,2,0) -> 1200 | E40: 992 | F40: =D40=E40 -> FALSE | G40: =VLOOKUP(B40,Sheet5!$A40:$C96,3,0) -> 1200 | H40: =D40-G40 -> 0 | I40: -64 | J40: =VLOOKUP(B40,Sheet5!A41:B93,2,0) -> 320 | K40: =VLOOKUP(B40,[2]Sheet2!$A:$F,6,0) -> 432 | L40: =VLOOKUP(B40,[4]Sheet1!$A:$B,2,0) -> 336 | M40: =K40-J40 -> 112 | N40: =M40+I40 -> 48 | O40: =N40/16 -> 3 | P40: =E40-K40 -> 560 | R40: =D40-L40 -> 864
B41: Penguard Express Ral 9018 (Part B) | C41: 180 | D41: =VLOOKUP(B41,[3]Sheet1!$A:$B,2,0) -> 312 | E41: 260 | F41: =D41=E41 -> FALSE | G41: =VLOOKUP(B41,Sheet5!$A41:$C97,3,0) -> 312 | H41: =D41-G41 -> 0 | I41: -80 | J41: =VLOOKUP(B41,Sheet5!A42:B94,2,0) -> 136 | K41: =VLOOKUP(B41,[2]Sheet2!$A:$F,6,0) -> 132 | L41: =VLOOKUP(B41,[4]Sheet1!$A:$B,2,0) -> 108 | M41: =K41-J41 -> -4 | N41: =M41+I41 -> -84 | O41: =N41/4 -> -21 | P41: =E41-K41 -> 128 | R41: =D41-L41 -> 204
...

Sheet Sheet2
B3: Items | C3: Issuance as per TALLY (A) as per 30th July | D3: Issuance as per TALLY (B) as per 28th Sept | E3: Issuance in system (C=A-B) | H3: Items | I3: Issue Ltr Qty in Paint Sheet (A) | J3: Issue Ltr Qty in Tally as on 28th Sept (B) | K3: Issue sheet vs Tally Stock (C=A-B) | L3: No. of Tins not issued in sheet
B4: HARDTOP WT8 RAL 7035 A (16.7 Ltr) | C4: 1202.4 | D4: 434.2 | E4: 768.2 | H4: HARDTOP WT8 RAL 7035 A (16.7 Ltr) | I4: 718.1 | J4: 768.2 | K4: -50.1 | L4: -3
B5: HARDTOP WT8 RAL 7035 B 3.3 Ltr | C5: 250.86 | D5: 99.06 | E5: 151.8 | H5: HARDTOP WT8 RAL 7035 B 3.3 Ltr | I5: 141.9 | J5: 151.8 | K5: -9.9 | L5: -3
B6: Hardtop WT8 RAL 9018 A 16.7 | C6: 317.3 | D6: 233.8 | E6: 83.5 | H6: Hardtop WT8 RAL 9018 A 16.7 | I6: 83.5 | J6: 83.5 | K6: 0 | L6: 0
B7: Hardtop WT8 RAL 9018 B 3.3 | C7: 52.8 | D7: 36.3 | E7: 16.5 | H7: Hardtop WT8 RAL 9018 B 3.3 | I7: 16.5 | J7: 16.5 | K7: 0 | L7: 0
B8: Hardtop XP Comp A RAL 2009 Traffic Orange | C8: 236.7 | D8: 35.1 | E8: 201.6 | H8: Hardtop XP Comp A RAL 2009 Traffic Orange | I8: 184.91 | J8: 201.6 | K8: -16.69 | L8: -1
B9: Hardtop XP Comp B RAL 2009 Traffic Orange | C9: 23.4 | D9: 1.8 | E9: 21.6 | H9: Hardtop XP Comp B RAL 2009 Traffic Orange | I9: 19.8 | J9: 21.6 | K9: -1.8 | L9: -1
B10: Hardtop XP II RAL 9003 Part A 16.02Ltrs. | C10: 1118.72 | D10: 315.56 | E10: 803.16 | H10: Hardtop XP II RAL 9003 Part A 16.02Ltrs. | I10: 801 | J10: 803.16 | K10: -2.16 | L10: 0
B11: Hardtop XP II RAL 9003 Part B 2.2Ltrs. | C11: 151.8 | D11: 41.8 | E11: 110 | H11: Hardtop XP II RAL 9003 Part B 2.2Ltrs. | I11: 110 | J11: 110 | K11: 0 | L11: 0
B12: Jotun Thinner No.10 | C12: 1110 | D12: 390 | E12: 720 | H12: Jotun Thinner No.10 | I12: 720 | J12: 720 | K12: 0 | L12: 0
B13: Jotun Thinner No.17 | C13: 1569.9 | D13: 169.9 | E13: 1400 | H13: Jotun Thinner No.17 | I13: 1240 | J13: 1400 | K13: -160 | L13: -8
B14: Paint Barrier 80 Part A | C14: 237 | D14: 205.5 | E14: 31.5 | H14: Paint Barrier 80 Part A | I14: 31.5 | J14: 31.5 | K14: 0 | L14: 0
B15: Paint Barrier 80 Part B | C15: 38.2 | D15: 33.2 | E15: 5 | H15: Paint Barrier 80 Part B | I15: 5 | J15: 5 | K15: 0 | L15: 0
... B23: Penguard Express Ral 9018 (Part B) | C23: 312 | D23: 108 | E23: 204 | H23: Penguard Express Ral 9018 (Part B) | I23: 96 | J23: 204 | K23: -108 | L23: -27
B24: Grand Total | E24: 15000.86 | H24: Grand Total | I24: 14448.21 | J24: 15000.86 | K24: -552.65 | L24: =SUM(L4:L23) -> -38
B25: Issuance as per Paint Stock Sheet | E25: 14448.21
B26: Diff tally vs Sheet | E26: 552.65
B29: Items | C29: Issue Ltr Qty in Paint Sheet (A) | D29: Issue Ltr Qty in Tally (B) | E29: Diff. (C=A-B) | F29: No. of Tins not issued in sheet
B30: HARDTOP WT8 RAL 7035 A (16.7 Ltr) | C30: 718.1 | D30: 768.2 | E30: -50.1 | F30: -3
B31: HARDTOP WT8 RAL 7035 B 3.3 Ltr | C31: 141.9 | D31: 151.8 | E31: -9.9 | F31: -3
B32: Hardtop XP Comp A RAL 2009 Traffic Orange | C32: 184.91 | D32: 201.6 | E32: -16.69 | F32: -1
B33: Hardtop XP Comp B RAL 2009 Traffic Orange | C33: 19.8 | D33: 21.6 | E33: -1.8 | F33: -1
B34: Hardtop XP II RAL 9003 Part A 16.02Ltrs. | C34: 801 | D34: 803.16 | E34: -2.16
B35: Jotun Thinner No.17 | C35: 1240 | D35: 1400 | E35: -160 | F35: -8
B36: Paint Penguard Express CF RAL 1013 Part A | C36: 76 | D36: 112 | E36: -36 | F36: 2
B37: Paint Penguard Express RAL 7035 Comp A | C37: 944 | D37: 992 | E37: -48 | F37: -3
B38: Paint Penguard Express RAL 7035 Comp. B | C38: 260 | D38: 232 | E38: 28 | F38: 7
B39: Penguard Express Gray Part A (16 Ltr) | C39: 6448 | D39: 6592 | E39: -144 | F39: -9
B40: Penguard Express Grey Part B (4 Ltr) | C40: 1708 | D40: 1664 | E40: 44 | F40: 11
B41: Penguard Express Ral 9018 (Part A) | C41: 816 | D41: 864 | E41: -48 | F41: -3
B42: Penguard Express Ral 9018 (Part B) | C42: 96 | D42: 204 | E42: -108 | F42: -27
B43: Grand Total | C43: 14448.21 | D43: 15000.86 | E43: -552.65

Sheet Working
H1: =SUBTOTAL(9,H3:H228) -> 24743.361 | I1: =SUBTOTAL(9,I3:I228) -> 1367 | J1: =SUBTOTAL(9,J3:J228) -> 4823.75 | K1: =SUBTOTAL(9,K3:K228) -> 14448.21 | L1: =SUBTOTAL(9,L3:L228) -> 9624.46 | M1: =SUBTOTAL(9,M3:M228) -> 10295.151
A2: Sr. No | B2: ICD | C2: Material Description | D2: Part No | E2: UOM | F2: Tin/Ltr | G2: No. Of Tins | H2: Total Ltr Qty | I2: Issue Tin Qty | J2: Issue Ltr Qty 30/7 | K2: Issue Ltr Qty 28/8 | L2: Diff. | M2: Balance Qty | N2: Remark | O2: Batch No | P2: Client | Q2: Container No. | R2: MFG Date | S2: Expiry Date | T2: Today Date | U2: Remaining Day left for expiry | V2: Status | W2: Final Remarks | X2: Procure | Y2: PO No | Z2: Remarks | AA2: Out/system | AB2: TOWER NO. SECTION NO.
A3: 55 | B3: Paint Barrier 80 Part A | C3: Barrier 80 Comp A | D3: A | E3: L | F3: 6.75 | G3: 1 | H3: =F3*G3 -> 6.75 | J3: 0 | K3: =I3*F3 -> 0 | L3: =K3-J3 -> 0 | M3: =H3-K3 -> 6.75 | N3: done | O3: 2859306 | P3: Ayana | Q3: 4 | R3: 44743 | S3: 45473 | T3: 45868 | U3: =S3-T3 -> -395 | V3: =IF(U3<0,"Expired","Not Expired") -> Expired | W3: =IF(U3<-45,"Expired more than 45 Days",IF(U3<0,"Recently Expired within 45 Days ago",IF(U3<=45,"Will be Expire within 45 Days","Not Expire"))) -> Expired more than 45 Days | X3: DFIPL Purchase | Y3: =VLOOKUP(O3,[5]Working!$F:$Q,12,0) -> DFIPL Purchase | Z3: Need to check date from system | AA3: System
A4: 104 | B4: Jotun Thinner No-25 | C4: Jotun Thinner No. 25 | E4: L | F4: 20 | G4: 1 | H4: =F4*G4 -> 20 | J4: 0 | K4: =I4*F4 -> 0 | L4: =K4-J4 -> 0 | M4: =H4-K4 -> 20 | N4: done | O4: 2566122 | P4: SGRE | Q4: 2 | R4: 44411 | S4: 45871 | T4: 45868 | U4: =S4-T4 -> 3 | V4: =IF(U4<0,"Expired","Not Expired") -> Not Expired | W4: =IF(U4<-45,"Expired more than 45 Days",IF(U4<0,"Recently Expired within 45 Days ago",IF(U4<=45,"Will be Expire within 45 Days","Not Expire"))) -> Will be Expire within 45 Days | X4: DFIPL Purchase | Y4: =VLOOKUP(O4,[5]Working!$F:$Q,12,0) -> DFIPL Purchase | Z4: NEED TO CHECK IN SYSTEM FOR DATE & CLIENT | AA4: System
A5: 117 | B5: Paint Barrier 80 Part B | C5: Barrier 80 Comp. B | D5: B | E5: L | F5: 2.25 | G5: 1 | H5: =F5*G5 -> 2.25 | J5: 0 | K5: =I5*F5 -> 0 | L5: =K5-J5 -> 0 | M5: =H5-K5 -> 2.25 | N5: done | O5: 2538093 | P5: COMMON USE | Q5: 4 | R5: 44376 | S5: 45106 | T5: 45868 | U5: =S5-T5 -> -762 | V5: =IF(U5<0,"Expired","Not Expired") -> Expired | W5: =IF(U5<-45,"Expired more than 45 Days",IF(U5<0,"Recently Expired within 45 Days ago",IF(U5<=45,"Will be Expire within 45 Days","Not Expire"))) -> Expired more than 45 Days | X5: DFIPL Purchase | Y5: =VLOOKUP(O5,[5]Working!$F:$Q,12,0) -> DFIPL Purchase | Z5: NEED TO CHECK FROM SYSTEM FOR DATE & PROJECT NAME | AA5: System
A6: 53 | B6: Thinner GTA 803 | C6: International Thinner GT 803 | E6: L | F6: 20 | G6: 1 | H6: =F6*G6 -> 20 | J6: 0 | K6: =I6*F6 -> 0 | L6: =K6-J6 -> 0 | M6: =H6-K6 -> 20 | N6: done | O6: Q0D000 | P6: Thermax | Q6: 4 | R6: 43831 | S6: 44562 | T6: 45868 | U6: =S6-T6 -> -1306 | V6: =IF(U6<0,"Expired","Not Expired") -> Expired | W6: =IF(U6<-45,"Expired more than 45 Days",IF(U6<0,"Recently Expired within 45 Days ago",IF(U6<=45,"Will be Expire within 45 Days","Not Expire"))) -> Expired more than 45 Days | X6: Customer | Y6: =VLOOKUP(O6,[5]Working!$F:$Q,12,0) -> #N/A | Z6: own purchased, reason | AA6: NR
A7: 98 | B7: Penguard Express Gray Part A (16 Ltr) | C7: Penguard Express Grey | D7: A | E7: L | F7: 16 | G7: 1 | H7: =F7*G7 -> 16 | J7: 0 | K7: =I7*F7 -> 0 | L7: =K7-J7 -> 0 | M7: =H7-K7 -> 16 | N7: done | O7: 2580592 | P7: Ayana | Q7: 4 | R7: 44431 | S7: 45161 | T7: 45868 | U7: =S7-T7 -> -707 | V7: =IF(U7<0,"Expired","Not Expired") -> Expired | W7: =IF(U7<-45,"Expired more than 45 Days",IF(U7<0,"Recently Expired within 45 Days ago",IF(U7<=45,"Will be Expire within 45 Days","Not Expire"))) -> Expired more than 45 Days | X7: DFIPL Purchase | Y7: =VLOOKUP(O7,[5]Working!$F:$Q,12,0) -> DFIPL Purchase | AA7: NR
A8: 56 | B8: Paint Barrier 80 Part A | C8: Paint Barrier 80 Part A | D8: A | E8: L | F8: 6.75 | G8: 1 | H8: 6.75 | J8: 0 | K8: =I8*F8 -> 0 | L8: =K8-J8 -> 0 | M8: =H8-K8 -> 6.75 | N8: done | O8: 2582705 | P8: Ayana | Q8: 4 | R8: 44432 | S8: 45162 | T8: 45868 | U8: =S8-T8 -> -706 | V8: =IF(U8<0,"Expired","Not Expired") -> Expired | W8: =IF(U8<-45,"Expired more than 45 Days",IF(U8<0,"Recently Expired within 45 Days ago",IF(U8<=45,"Will be Expire within 45 Days","Not Expire"))) -> Expired more than 45 Days | X8: DFIPL Purchase | Y8: =VLOOKUP(O8,[5]Working!$F:$Q,12,0) -> DFIPL Purchase | AA8: NR
A9: 166 | B9: Paint Penguard Express CF RAL 1013 Part A | C9: Penguard Express CF RAL 1013 | D9: A | E9: L | F9: 16 | G9: 2 | H9: =F9*G9 -> 32 | J9: 0 | K9: =I9*F9 -> 0 | L9: =K9-J9 -> 0 | M9: =H9-K9 -> 32 | N9: done | O9: 2580915 | P9: SGRE | Q9: 2 | R9: 44432 | S9: 45162 | T9: 45868 | U9: =S9-T9 -> -706 | V9: =IF(U9<0,"Expired","Not Expired") -> Expired | W9: =IF(U9<-45,"Expired more than 45 Days",IF(U9<0,"Recently Expired within 45 Days ago",IF(U9<=45,"Will be Expire within 45 Days","Not Expire"))) -> Expired more than 45 Days | X9: DFIPL Purchase | Y9: =VLOOKUP(O9,[5]Working!$F:$Q,12,0) -> DFIPL Purchase | AA9: NR
A10: 115 | B10: Penguard Express Grey Part B (4 Ltr) | C10: Penguard Express Comp B | D10: B | E10: L | F10: 4 | G10: 1 | H10: =F10*G10 -> 4 | J10: 0 | K10: =I10*F10 -> 0 | L10: =K10-J10 -> 0 | M10: =H10-K10 -> 4 | N10: done | O10: 3231239 | P10: Ayana | Q10: 4 | R10: 44433 | S10: 45163 | T10: 45868 | U10: =S10-T10 -> -705 | V10: =IF(U10<0,"Expired","Not Expired") -> Expired | W10: =IF(U10<-45,"Expired more than 45 Days",IF(U10<0,"Recently Expired within 45 Days ago",IF(U10<=45,"Will be Expire within 45 Days","Not Expire"))) -> Expired more than 45 Days | X10: DFIPL Purchase | Y10: =VLOOKUP(O10,[5]Working!$F:$Q,12,0) -> DFIPL Purchase | AA10: NR
A11: 49 | B11: Interguard 475HS Ral Tropical | C11: International Interguard 475 HS | D11: B | E11: L | F11: 5 | G11: 2 | H11: =F11*G11 -> 10 | J11: 0 | K11: =I11*F11 -> 0 | L11: =K11-J11 -> 0 | M11: =H11-K11 -> 10 | N11: done | O11: Q0D2354053 | P11: Thermax | Q11: 4 | R11: 44896 | S11: 45261 | T11: 45868 | U11: =S11-T11 -> -607 | V11: =IF(U11<0,"Expired","Not Expired") -> Expired | W11: =IF(U11<-45,"Expired more than 45 Days",IF(U11<0,"Recently Expired within 45 Days ago",IF(U11<=45,"Will be Expire within 45 Days","Not Expire"))) -> Expired more than 45 Days | X11: Customer | Y11: =VLOOKUP(O11,[5]Working!$F:$Q,12,0) -> #N/A | Z11: own purchased, reason | AA11: NR
A12: 167 | B12: Paint Penguard Express CF RAL 1013 Part A | C12: Penguard Express CF RAL 1013 | D12: A | E12: L | F12: 16 | G12: 1 | H12: =F12*G12 -> 16 | J12: 0 | K12: =I12*F12 -> 0 | L12: =K12-J12 -> 0 | M12: =H12-K12 -> 16 | N12: done | O12: 3178665 | P12: SGRE | Q12: 2 | R12: 45091 | S12: 46003 | T12: 45868 | U12: =S12-T12 -> 135 | V12: =IF(U12<0,"Expired","Not Expired") -> Not Expired | W12: =IF(U12<-45,"Expired more than 45 Days",IF(U12<0,"Recently Expired within 45 Days ago",IF(U12<=45,"Will be Expire within 45 Days","Not Expire"))) -> Not Expire | X12: DFIPL Purchase | Y12: =VLOOKUP(O12,[5]Working!$F:$Q,12,0) -> DFIPL Purchase | AA12: NR
A13: 50 | B13: Interprime 198 CPA 098 | C13: International Interprime 198 | D13: A | E13: L | F13: 20 | G13: 5 | H13: =F13*G13 -> 100 | J13: 0 | K13: =I13*F13 -> 0 | L13: =K13-J13 -> 0 | M13: =H13-K13 -> 100 | N13: done | O13: Q0D2029004 | P13: Thermax | Q13: 4 | R13: 44593 | S13: 45323 | T13: 45868 | U13: =S13-T13 -> -545 | V13: =IF(U13<0,"Expired","Not Expired") -> Expired | W13: =IF(U13<-45,"Expired more than 45 Days",IF(U13<0,"Recently Expired within 45 Days ago",IF(U13<=45,"Will be Expire within 45 Days","Not Expire"))) -> Expired more than 45 Days | X13: Customer | Y13: =VLOOKUP(O13,[5]Working!$F:$Q,12,0) -> #N/A | Z13: own purchased, reason | AA13: NR
A14: 54 | B14: Interlac 665 Ral 1017CLS179 | C14: International Interlax 665 RAL 1017 | D14: A | E14: L | F14: 20 | G14: 4 | H14: =F14*G14 -> 80 | J14: 0 | K14: =I14*F14 -> 0 | L14: =K14-J14 -> 0 | M14: =H14-K14 -> 80 | N14: done | O14: YB4100GZ | P14: Thermax | Q14: 4 | R14: 44593 | S14: 45323 | T14: 45868 | U14: =S14-T14 -> -545 | V14: =IF(U14<0,"Expired","Not Expired") -> Expired | W14: =IF(U14<-45,"Expired more than 45 Days",IF(U14<0,"Recently Expired within 45 Days ago",IF(U14<=45,"Will be Expire within 45 Days","Not Expire"))) -> Expired more than 45 Days | X14: Customer | Y14: =VLOOKUP(O14,[5]Working!$F:$Q,12,0) -> #N/A | Z14: own purchased, reason | AA14: NR
A15: 173 | B15: Penguard Express Gray Part A (16 Ltr) | C15: Penguard Express Grey | D15: A | E15: L | F15: 16 | G15: 1 | H15: =F15*G15 -> 16 | J15: 0 | K15: =I15*F15 -> 0 | L15: =K15-J15 -> 0 | M15: =H15-K15 -> 16 | N15: done | O15: 2736868 | P15: SGRE | Q15: 2 | R15: 44608 | S15: 45338 | T15: 45868 | U15: =S15-T15 -> -530 | V15: =IF(U15<0,"Expired","Not Expired") -> Expired | W15: =IF(U15<-45,"Expired more than 45 Days",IF(U15<0,"Recently Expired within 45 Days ago",IF(U15<=45,"Will be Expire within 45 Days","Not Expire"))) -> Expired more than 45 Days | X15: DFIPL Purchase | Y15: =VLOOKUP(O15,[5]Working!$F:$Q,12,0) -> DFIPL Purchase | AA15: NR
A16: 52 | B16: Interguard 475HS Ral 7035 | C16: International Interguard 475 HS RAL 7035 | D16: B | E16: L | F16: 15 | G16: 2 | H16: =F16*G16 -> 30 | J16: 0 | K16: =I16*F16 -> 0 | L16: =K16-J16 -> 0 | M16: =H16-K16 -> 30 | N16: done | O16: Q0D2326006 | P16: Thermax | Q16: 4 | R16: 44866 | S16: 45413 | T16: 45868 | U16: =S16-T16 -> -455 | V16: =IF(U16<0,"Expired","Not Expired") -> Expired | W16: =IF(U16<-45,"Expired more than 45 Days",IF(U16<0,"Recently Expired within 45 Days ago",IF(U16<=45,"Will be Expire within 45 Days","Not Expire"))) -> Expired more than 45 Days | X16: Customer | Y16: =VLOOKUP(O16,[5]Working!$F:$Q,12,0) -> #N/A | Z16: own purchased, reason | AA16: NR
A17: 209 | B17: Paint Penguard Express CF RAL 1013 Part B | C17: Penguard Express CF Comp B | D17: B | E17: L | F17: 4 | G17: 1 | H17: =F17*G17 -> 4 | J17: 0 | K17: =I17*F17 -> 0 | L17: =K17-J17 -> 0 | M17: =H17-K17 -> 4 | N17: done | O17: 2811085 | P17: SGRE | Q17: 2 | R17: 44692 | S17: 45422 | T17: 45868 | U17: =S17-T17 -> -446 | V17: =IF(U17<0,"Expired","Not Expired") -> Expired | W17: =IF(U17<-45,"Expired more than 45 Days",IF(U17<0,"Recently Expired within 45 Days ago",IF(U17<=45,"Will be Expire within 45 Days","Not Expire"))) -> Expired more than 45 Days | X17: DFIPL Purchase | Y17: =VLOOKUP(O17,[5]Working!$F:$Q,12,0) -> DFIPL Purchase | AA17: NR
A18: 210 | B18: Paint Penguard Express CF RAL 1013 Part B | C18: Penguard Express CF Comp B | D18: B | E18: L | F18: 4 | G18: 1 | H18: =F18*G18 -> 4 | J18: 0 | K18: =I18*F18 -> 0 | L18: =K18-J18 -> 0 | M18: =H18-K18 -> 4 | N18: done | O18: 2853805 | P18: SGRE | Q18: 2 | R18: 44739 | S18: 45469 | T18: 45868 | U18: =S18-T18 -> -399 | V18: =IF(U18<0,"Expired","Not Expired") -> Expired | W18: =IF(U18<-45,"Expired more than 45 Days",IF(U18<0,"Recently Expired within 45 Days ago",IF(U18<=45,"Will be Expire within 45 Days","Not Expire"))) -> Expired more than 45 Days | X18: DFIPL Purchase | Y18: =VLOOKUP(O18,[5]Working!$F:$Q,12,0) -> DFIPL Purchase | AA18: NR
A19: 226 | B19: Paint Barrier 80 Part B | C19: Barrier 80 Comp. B | D19: B | E19: L | F19: 2.25 | G19: 2 | H19: =F19*G19 -> 4.5 | J19: 0 | K19: =I19*F19 -> 0 | L19: =K19-J19 -> 0 | M19: =H19-K19 -> 4.5 | N19: done | O19: 2859331 | P19: SGRE | Q19: 2 | R19: 44743 | S19: 45473 | T19: 45868 | U19: =S19-T19 -> -395 | V19: =IF(U19<0,"Expired","Not Expired") -> Expired | W19: =IF(U19<-45,"Expired more than 45 Days",IF(U19<0,"Recently Expired within 45 Days ago",IF(U19<=45,"Will be Expire within 45 Days","Not Expire"))) -> Expired more than 45 Days | X19: DFIPL Purchase | Y19: =VLOOKUP(O19,[5]Working!$F:$Q,12,0) -> DFIPL Purchase | AA19: NR
A20: 48 | B20: Interthane 990 | C20: International Interthane 990 | D20: B | E20: L | F20: 2.86 | G20: 1 | H20: =F20*G20 -> 2.86 | J20: 0 | K20: =I20*F20 -> 0 | L20: =K20-J20 -> 0 | M20: =H20-K20 -> 2.86 | N20: done | O20: Q0D3046002 | P20: Thermax | Q20: 4 | R20: 44958 | S20: 45505 | T20: 45868 | U20: =S20-T20 -> -363 | V20: =IF(U20<0,"Expired","Not Expired") -> Expired | W20: =IF(U20<-45,"Expired more than 45 Days",IF(U20<0,"Recently Expired within 45 Days ago",IF(U20<=45,"Will be Expire within 45 Days","Not Expire"))) -> Expired more than 45 Days | X20: Customer | Y20: =VLOOKUP(O20,[5]Working!$F:$Q,12,0) -> #N/A | Z20: own purchased, reason | AA20: NR
A21: 169 | B21: Barrier 80X A | C21: Barrier 80 X Comp A | D21: A | E21: L | F21: 9 | G21: 1 | H21: =F21*G21 -> 9 | J21: 0 | K21: =I21*F21 -> 0 | L21: =K21-J21 -> 0 | M21: =H21-K21 -> 9 | N21: done | O21: 3236808 | P21: Renew | Q21: 2 | R21: 45152 | S21: 45517 | T21: 45868 | U21: =S21-T21 -> -351 | V21: =IF(U21<0,"Expired","Not Expired") -> Expired | W21: =IF(U21<-45,"Expired more than 45 Days",IF(U21<0,"Recently Expired within 45 Days ago",IF(U21<=45,"Will be Expire within 45 Days","Not Expire"))) -> Expired more than 45 Days | X21: Customer | Y21: =VLOOKUP(O21,[5]Working!$F:$Q,12,0) -> #N/A | Z21: reason | AA21: NR
A22: 107 | B22: Hempaprime multi 500 A | C22: Hemaprime Multi 500 | D22: A | E22: L | F22: 16 | G22: 5 | H22: =F22*G22 -> 80 | J22: 0 | K22: =I22*F22 -> 0 | L22: =K22-J22 -> 0 | M22: =H22-K22 -> 80 | N22: done | O22: 73035266 | P22: Senvion | Q22: 4 | R22: 45030 | S22: 45518 | T22: 45868 | U22: =S22-T22 -> -350 | V22: =IF(U22<0,"Expired","Not Expired") -> Expired | W22: =IF(U22<-45,"Expired more than 45 Days",IF(U22<0,"Recently Expired within 45 Days ago",IF(U22<=45,"Will be Expire within 45 Days","Not Expire"))) -> Expired more than 45 Days | X22: Customer | Y22: =VLOOKUP(O22,[5]Working!$F:$Q,12,0) -> #N/A | Z22: reason | AA22: NR
A23: 51 | B23: Interprime 198 CPA 098 | C23: International Interprime 198 | D23: A | E23: L | F23: 20 | G23: 3 | H23: =F23*G23 -> 60 | J23: 0 | K23: =I23*F23 -> 0 | L23: =K23-J23 -> 0 | M23: =H23-K23 -> 60 | N23: done | O23: Q0D2272028 | P23: Thermax | Q23: 4 | R23: 44835 | S23: 45566 | T23: 45868 | U23: =S23-T23 -> -302 | V23: =IF(U23<0,"Expired","Not Expired") -> Expired | W23: =IF(U23<-45,"Expired more than 45 Days",IF(U23<0,"Recently Expired within 45 Days ago",IF(U23<=45,"Will be Expire within 45 Days","Not Expire"))) -> Expired more than 45 Days | X23: Customer | Y23: =VLOOKUP(O23,[5]Working!$F:$Q,12,0) -> #N/A | Z23: own purchased, reason | AA23: NR
A24: 86 | B24: Jotun Thinner No.17 | C24: Jotun Thinner No. 17 | E24: L | F24: 20 | G24: 4 | H24: =F24*G24 -> 80 | I24: 1 | J24: 20 | K24: =I24*F24 -> 20 | L24: =K24-J24 -> 0 | M24: =H24-K24 -> 60 | N24: done | O24: 3682857 | P24: Ayana | Q24: 4 | R24: 45575 | S24: 45574 | T24: 45868 | U24: =S24-T24 -> -294 | V24: =IF(U24<0,"Expired","Not Expired") -> Expired | W24: =IF(U24<-45,"Expired more than 45 Days",IF(U24<0,"Recently Expired within 45 Days ago",IF(U24<=45,"Will be Expire within 45 Days","Not Expire"))) -> Expired more than 45 Days | X24: DFIPL Purchase | Y24: =VLOOKUP(O24,[5]Working!$F:$Q,12,0) -> DFIPL Purchase | AA24: NR | AB24: SGRE 620215 S5 Dt. 14.07.2025
A25: 212 | B25: OC2 JotaMastic 80 Grey Part A | C25: Jotumastic 80 Grey A | D25: A | E25: L | F25: 16 | G25: 1 | H25: =F25*G25 -> 16 | J25: 0 | K25: =I25*F25 -> 0 | L25: =K25-J25 -> 0 | M25: =H25-K25 -> 16 | N25: Done | O25: 2415759 | P25: SGRE | Q25: 2 | R25: 44230 | S25: 45690 | T25: 45868 | U25: =S25-T25 -> -178 | V25: =IF(U25<0,"Expired","Not Expired") -> Expired | W25: =IF(U25<-45,"Expired more than 45 Days",IF(U25<0,"Recently Expired within 45 Days ago",IF(U25<=45,"Will be Expire within 45 Days","Not Expire"))) -> Expired more than 45 Days | X25: DFIPL Purchase | Y25: =VLOOKUP(O25,[5]Working!$F:$Q,12,0) -> DFIPL Purchase | AA25: NR
A26: 65 | B26: ACME Paint Hardtop XP, Part A Black Ral-9005 | C26: Hardtop XP Base 3A | D26: A | E26: L | F26: 17.39 | G26: 1 | H26: =F26*G26 -> 17.39 | J26: 0 | K26: =I26*F26 -> 0 | L26: =K26-J26 -> 0 | M26: =H26-K26 -> 17.39 | N26: Done | O26: 2418301 | P26: Ayana | Q26: 4 | R26: 44232 | S26: 45692 | T26: 45868 | U26: =S26-T26 -> -176 | V26: =IF(U26<0,"Expired","Not Expired") -> Expired | W26: =IF(U26<-45,"Expired more than 45 Days",IF(U26<0,"Recently Expired within 45 Days ago",IF(U26<=45,"Will be Expire within 45 Days","Not Expire"))) -> Expired more than 45 Days | X26: DFIPL Purchase | Y26: =VLOOKUP(O26,[5]Working!$F:$Q,12,0) -> DFIPL Purchase | AA26: NR
A27: 197 | B27: Hardtop WT8 RAL 9018 A 16.7 | C27: Hardtop WT8 RAL 9018 | D27: A | E27: L | F27: 16.7 | G27: 4 | H27: =F27*G27 -> 66.8 | J27: 0 | K27: =I27*F27 -> 0 | L27: =K27-J27 -> 0 | M27: =H27-K27 -> 66.8 | N27: done | O27: 2422866 | P27: SGRE | Q27: 2 | R27: 44237 | S27: 45697 | T27: 45868 | U27: =S27-T27 -> -171 | V27: =IF(U27<0,"Expired","Not Expired") -> Expired | W27: =IF(U27<-45,"Expired more than 45 Days",IF(U27<0,"Recently Expired within 45 Days ago",IF(U27<=45,"Will be Expire within 45 Days","Not Expire"))) -> Expired more than 45 Days | X27: DFIPL Purchase | Y27: =VLOOKUP(O27,[5]Working!$F:$Q,12,0) -> DFIPL Purchase | AA27: NR
A28: 58 | B28: Penguard Express Gray Part A (16 Ltr) | C28: Penguard Express Grey | D28: A | E28: L | F28: 16 | G28: 1 | H28: =F28*G28 -> 16 | J28: 0 | K28: =I28*F28 -> 0 | L28: =K28-J28 -> 0 | M28: =H28-K28 -> 16 | N28: done | O28: 3061070 | P28: Ayana | Q28: 4 | R28: 44972 | S28: 45702 | T28: 45868 | U28: =S28-T28 -> -166 | V28: =IF(U28<0,"Expired","Not Expired") -> Expired | W28: =IF(U28<-45,"Expired more than 45 Days",IF(U28<0,"Recently Expired within 45 Days ago",IF(U28<=45,"Will be Expire within 45 Days","Not Expire"))) -> Expired more than 45 Days | X28: DFIPL Purchase | Y28: =VLOOKUP(O28,[5]Working!$F:$Q,12,0) -> DFIPL Purchase | AA28: NR
A29: 106 | B29: Hempathane HS 55610 A 9002 | C29: Hempathane HS 55610 | D29: A | E29: L | F29: 17.5 | G29: 1 | H29: =F29*G29 -> 17.5 | J29: 0 | K29: =I29*F29 -> 0 | L29: =K29-J29 -> 0 | M29: =H29-K29 -> 17.5 | N29: done | O29: 73025053 | P29: Senvion | Q29: 4 | R29: 44971 | S29: 45702 | T29: 45868 | U29: =S29-T29 -> -166 | V29: =IF(U29<0,"Expired","Not Expired") -> Expired | W29: =IF(U29<-45,"Expired more than 45 Days",IF(U29<0,"Recently Expired within 45 Days ago",IF(U29<=45,"Will be Expire within 45 Days","Not Expire"))) -> Expired more than 45 Days | X29: Customer | Y29: =VLOOKUP(O29,[5]Working!$F:$Q,12,0) -> #N/A | Z29: reason | AA29: NR
A30: 174 | B30: Penguard Express Gray Part A (16 Ltr) | C30: Penguard Express Grey | D30: A | E30: L | F30: 16 | G30: 1 | H30: =F30*G30 -> 16 | J30: 0 | K30: =I30*F30 -> 0 | L30: =K30-J30 -> 0 | M30: =H30-K30 -> 16 | N30: done | O30: 3061070 | P30: SGRE | Q30: 2 | R30: 44972 | S30: 45702 | T30: 45868 | U30: =S30-T30 -> -166 | V30: =IF(U30<0,"Expired","Not Expired") -> Expired | W30: =IF(U30<-45,"Expired more than 45 Days",IF(U30<0,"Recently Expired within 45 Days ago",IF(U30<=45,"Will be Expire within 45 Days","Not Expire"))) -> Expired more than 45 Days | X30: DFIPL Purchase | Y30: =VLOOKUP(O30,[5]Working!$F:$Q,12,0) -> DFIPL Purchase | AA30: NR
A31: 108 | B31: Penguard Express Ral 9018 (Part A) | C31: Penguard Express RAL 9018 | D31: A | E31: L | F31: 16 | G31: 1 | H31: =F31*G31 -> 16 | J31: 0 | K31: =I31*F31 -> 0 | L31: =K31-J31 -> 0 | M31: =H31-K31 -> 16 | N31: done | O31: 3070411 | P31: Ayana | Q31: 4 | R31: 44981 | S31: 45711 | T31: 45868 | U31: =S31-T31 -> -157 | V31: =IF(U31<0,"Expired","Not Expired") -> Expired | W31: =IF(U31<-45,"Expired more than 45 Days",IF(U31<0,"Recently Expired within 45 Days ago",IF(U31<=45,"Will be Expire within 45 Days","Not Expire"))) -> Expired more than 45 Days | X31: DFIPL Purchase | Y31: =VLOOKUP(O31,[5]Working!$F:$Q,12,0) -> DFIPL Purchase | AA31: NR
A32: 59 | B32: Hardtop XP 1021 A | C32: Hardtop XP 1021 A | D32: A | E32: L | F32: 16.83 | G32: 1 | H32: =F32*G32 -> 16.83 | J32: 0 | K32: =I32*F32 -> 0 | L32: =K32-J32 -> 0 | M32: =H32-K32 -> 16.83 | N32: done | O32: 2426573 | P32: Ayana | Q32: 4 | R32: 44261 | S32: 45721 | T32: 45868 | U32: =S32-T32 -> -147 | V32: =IF(U32<0,"Expired","Not Expired") -> Expired | W32: =IF(U32<-45,"Expired more than 45 Days",IF(U32<0,"Recently Expired within 45 Days ago",IF(U32<=45,"Will be Expire within 45 Days","Not Expire"))) -> Expired more than 45 Days | X32: DFIPL Purchase | Y32: =VLOOKUP(O32,[5]Working!$F:$Q,12,0) -> DFIPL Purchase | AA32: NR
A33: 105 | B33: Hempaprime multi 5561B 7035 | C33: Hempathane HS 5561 | D33: A | E33: L | F33: 17.5 | G33: 7 | H33: =F33*G33 -> 122.5 | J33: 0 | K33: =I33*F33 -> 0 | L33: =K33-J33 -> 0 | M33: =H33-K33 -> 122.5 | N33: done | O33: 73045293 | P33: Senvion | Q33: 4 | R33: 45044 | S33: 45775 | T33: 45868 | U33: =S33-T33 -> -93 | V33: =IF(U33<0,"Expired","Not Expired") -> Expired | W33: =IF(U33<-45,"Expired more than 45 Days",IF(U33<0,"Recently Expired within 45 Days ago",IF(U33<=45,"Will be Expire within 45 Days","Not Expire"))) -> Expired more than 45 Days | X33: Customer | Y33: =VLOOKUP(O33,[5]Working!$F:$Q,12,0) -> #N/A | Z33: reason | AA33: NR
A34: 176 | B34: Penguard Exp. Gray | C34: Penguard Express Grey | D34: A | E34: L | F34: 16 | G34: 2 | H34: =F34*G34 -> 32 | J34: 0 | K34: =I34*F34 -> 0 | L34: =K34-J34 -> 0 | M34: =H34-K34 -> 32 | N34: done | O34: 3188271 | P34: Renew | Q34: 2 | R34: 45099 | S34: 45829 | T34: 45868 | U34: =S34-T34 -> -39 | V34: =IF(U34<0,"Expired","Not Expired") -> Expired | W34: =IF(U34<-45,"Expired more than 45 Days",IF(U34<0,"Recently Expired within 45 Days ago",IF(U34<=45,"Will be Expire within 45 Days","Not Expire"))) -> Recently Expired within 45 Days ago | X34: Customer | Y34: =VLOOKUP(O34,[5]Working!$F:$Q,12,0) -> #N/A | Z34: reason | AA34: NR
A35: 177 | B35: Penguard Exp. Gray | C35: Penguard Express Grey | D35: A | E35: L | F35: 16 | G35: 5 | H35: =F35*G35 -> 80 | J35: 0 | K35: =I35*F35 -> 0 | L35: =K35-J35 -> 0 | M35: =H35-K35 -> 80 | N35: done | O35: 3188354 | P35: Renew | Q35: 2 | R35: 45099 | S35: 45829 | T35: 45868 | U35: =S35-T35 -> -39 | V35: =IF(U35<0,"Expired","Not Expired") -> Expired | W35: =IF(U35<-45,"Expired more than 45 Days",IF(U35<0,"Recently Expired within 45 Days ago",IF(U35<=45,"Will be Expire within 45 Days","Not Expire"))) -> Recently Expired within 45 Days ago | X35: Customer | Y35: =VLOOKUP(O35,[5]Working!$F:$Q,12,0) -> #N/A | Z35: reason | AA35: NR
A36: 217 | B36: Paint Resisit 86 Part A 8 | C36: Resist 86 Grey A | D36: A | E36: L | F36: 8 | G36: 3 | H36: =F36*G36 -> 24 | J36: 0 | K36: =I36*F36 -> 0 | L36: =K36-J36 -> 0 | M36: =H36-K36 -> 24 | N36: done | O36: 3773005 | P36: SGRE | Q36: 2 | R36: 45645 | S36: 45834 | T36: 45868 | U36: =S36-T36 -> -34 | V36: =IF(U36<0,"Expired","Not Expired") -> Expired | W36: =IF(U36<-45,"Expired more than 45 Days",IF(U36<0,"Recently Expired within 45 Days ago",IF(U36<=45,"Will be Expire within 45 Days","Not Expire"))) -> Recently Expired within 45 Days ago | X36: DFIPL Purchase | Y36: =VLOOKUP(O36,[5]Working!$F:$Q,12,0) -> DFIPL Purchase | AA36: NR
A37: 225 | B37: Paint Barrier 80 Part B | C37: Barrier 80 X Comp. B | D37: B | E37: L | F37: 1.8 | G37: 2 | H37: =F37*G37 -> 3.6 | J37: 0 | K37: =I37*F37 -> 0 | L37: =K37-J37 -> 0 | M37: =H37-K37 -> 3.6 | N37: done | O37: 3215909 | P37: SGRE | Q37: 2 | R37: 45131 | S37: 45861 | T37: 45868 | U37: =S37-T37 -> -7 | V37: =IF(U37<0,"Expired","Not Expired") -> Expired | W37: =IF(U37<-45,"Expired more than 45 Days",IF(U37<0,"Recently Expired within 45 Days ago",IF(U37<=45,"Will be Expire within 45 Days","Not Expire"))) -> Recently Expired within 45 Days ago | X37: DFIPL Purchase | Y37: =VLOOKUP(O37,[5]Working!$F:$Q,12,0) -> DFIPL Purchase | AA37: NR
A38: 216 | B38: Penguard Exp. 9018 A | C38: Penguard Express RAL 9018 | D38: A | E38: L | F38: 16 | G38: 1 | H38: =F38*G38 -> 16 | J38: 0 | K38: =I38*F38 -> 0 | L38: =K38-J38 -> 0 | M38: =H38-K38 -> 16 | N38: done | O38: 3221407 | P38: Renew | Q38: 2 | R38: 45135 | S38: 45865 | T38: 45868 | U38: =S38-T38 -> -3 | V38: =IF(U38<0,"Expired","Not Expired") -> Expired | W38: =IF(U38<-45,"Expired more than 45 Days",IF(U38<0,"Recently Expired within 45 Days ago",IF(U38<=45,"Will be Expire within 45 Days","Not Expire"))) -> Recently Expired within 45 Days ago | X38: Customer | Y38: =VLOOKUP(O38,[5]Working!$F:$Q,12,0) -> #N/A | AA38: NR
A39: 32 | B39: Paint Barrier 80 Part A | C39: Jotun Barrier 80S Grey A | D39: A | E39: L | F39: 7.5 | G39: 2 | H39: =F39*G39 -> 15 | J39: 0 | K39: =I39*F39 -> 0 | L39: =K39-J39 -> 0 | M39: =H39-K39 -> 15 | N39: done | O39: 3231343 | P39: Ayana | Q39: 4 | R39: 45146 | S39: 45876 | T39: 45868 | U39: =S39-T39 -> 8 | V39: =IF(U39<0,"Expired","Not Expired") -> Not Expired | W39: =IF(U39<-45,"Expired more than 45 Days",IF(U39<0,"Recently Expired within 45 Days ago",IF(U39<=45,"Will be Expire within 45 Days","Not Expire"))) -> Will be Expire within 45 Days | X39: DFIPL Purchase | Y39: =VLOOKUP(O39,[5]Working!$F:$Q,12,0) -> DFIPL Purchase | AA39: NR
A40: 180 | B40: Penguard Express Grey Part B (4 Ltr) | C40: Penguard Express Comp B | D40: B | E40: L | F40: 4 | G40: 9 | H40: =F40*G40 -> 36 | I40: 9 | J40: 0 | K40: =I40*F40 -> 36 | L40: =K40-J40 -> 36 | M40: =H40-K40 -> 0 | N40: Done | O40: 3249888 | P40: SGRE | Q40: 2 | R40: 45163 | S40: 45893 | T40: 45868 | U40: =S40-T40 -> 25 | V40: =IF(U40<0,"Expired","Not Expired") -> Not Expired | W40: =IF(U40<-45,"Expired more than 45 Days",IF(U40<0,"Recently Expired within 45 Days ago",IF(U40<=45,"Will be Expire within 45 Days","Not Expire"))) -> Will be Expire within 45 Days | X40: DFIPL Purchase | Y40: =VLOOKUP(O40,[5]Working!$F:$Q,12,0) -> DFIPL Purchase | AA40: NR | AB40: SGRE 620173 S3 DT. 02.08.2025
...

Sheet Sheet6
A1: Row Labels | B1: a
A2: HARDTOP WT8 RAL 7035 A (16.7 Ltr) | B2: 167 | C2: =B2/16.7 -> 10 | D2: done
A3: HARDTOP WT8 RAL 7035 B 3.3 Ltr | B3: 33 | C3: =B3/3.3 -> 10 | D3: done
A4: Hardtop XP Comp A RAL 2009 Traffic Orange | B4: 67.2 | C4: =B4/16.81 -> 3.9976205 | D4: done
A5: Hardtop XP Comp B RAL 2009 Traffic Orange | B5: 7.2 | C5: =B5/1.8 -> 4
A6: Hardtop XP II RAL 9003 Part A 16.02Ltrs. | B6: 368.82 | C6: =B6/16.02 -> 23.022472 | D6: done
A7: Hardtop XP II RAL 9003 Part B 2.2Ltrs. | B7: 50.6 | C7: =B7/2.2 -> 23 | D7: done
A8: Jotun Thinner No.10 | B8: 200 | C8: =B8/20 -> 10 | D8: done | E8: 6
A9: Jotun Thinner No.17 | B9: 440 | C9: =B9/20 -> 22 | D9: done
A10: Paint Barrier 80 Part A | B10: 9 | C10: =B10/9 -> 1 | D10: done
A11: Paint Barrier 80 Part B | B11: 1.25 | C11: 1 | D11: done
A12: Paint Penguard Express RAL 7035 Comp A | B12: 464 | C12: =B12/16 -> 29 | D12: done
A13: Paint Penguard Express RAL 7035 Comp. B | B13: 100 | C13: =B13/4 -> 25 | D13: done
A14: Penguard Express Gray Part A (16 Ltr) | B14: 2144 | C14: =B14/16 -> 134 | D14: done
A15: Penguard Express Grey Part B (4 Ltr) | B15: 552 | C15: =B15/4 -> 138 | D15: done
A16: Penguard Express Ral 9018 (Part A) | B16: 208 | C16: =B16/16 -> 13 | D16: done
A17: Penguard Express Ral 9018 (Part B) | B17: 52 | C17: =B17/4 -> 13
B18: =SUM(B2:B17) -> 4864.07 | C18: =Working!K1 -> 14448.21 | D18: =C18-B18 -> 9584.14

Sheet Summary
A3: Status | B3: Final Remarks | C3: Client | D3: Sum of No. Of Tins | E3: Sum of Total Ltr Qty | F3: % wise contribution
A4: Expired | B4: Expired more than 45 Days | C4: Adani | D4: 12 | E4: 102
A5: Expired | B5: Expired more than 45 Days | C5: Ayana | D5: 12 | E5: 179.72
A6: Expired | B6: Expired more than 45 Days | C6: Renew | D6: 1 | E6: 9
A7: Expired | B7: Expired more than 45 Days | C7: Senvion | D7: 13 | E7: 220
A8: Expired | B8: Expired more than 45 Days | C8: SGRE | D8: 13 | E8: 159.3
A9: Expired | B9: Expired more than 45 Days | C9: Thermax | D9: 18 | E9: 302.86
A10: Expired | B10: Expired more than 45 Days | C10: COMMON USE | D10: 1 | E10: 2.25
A11: Expired | B11: Expired more than 45 Days Total | D11: 70 | E11: 975.13
A12: Expired | B12: Recently Expired within 45 Days ago | C12: Renew | D12: 8 | E12: 128
A13: Expired | B13: Recently Expired within 45 Days ago | C13: SGRE | D13: 6 | E13: 47.6
A14: Expired | B14: Recently Expired within 45 Days ago Total | D14: 14 | E14: 175.6 | F14: =E14/$E$29 -> 0.0041100692
A15: Expired Total | D15: 84 | E15: 1150.73
A16: Not Expired | B16: Will be Expire within 45 Days | C16: Ayana | D16: 43 | E16: 329
A17: Not Expired | B17: Will be Expire within 45 Days | C17: SGRE | D17: 35 | E17: 242.4
A18: Not Expired | B18: Will be Expire within 45 Days Total | D18: 78 | E18: 571.4
A19: Not Expired | B19: Not Expire | C19: ACME 2.O | D19: 1032 | E19: 10759.621
A20: Not Expired | B20: Not Expire | C20: Adani | D20: 728 | E20: 7585
A21: Not Expired | B21: Not Expire | C21: Ayana | D21: 149 | E21: 1657.22
A22: Not Expired | B22: Not Expire | C22: INOX | D22: 974 | E22: 10076.85
A23: Not Expired | B23: Not Expire | C23: Renew | D23: 32 | E23: 421.2
A24: Not Expired | B24: Not Expire | C24: SGRE | D24: 293 | E24: 3190.2
A25: Not Expired | B25: Not Expire | C25: Welspun | D25: 809 | E25: 8450.25
A26: Not Expired | B26: Not Expire | C26: COMMON USE | D26: 1 | E26: 9
A27: Not Expired | B27: Not Expire | C27: ACME | D27: 2 | E27: 3.6
A28: Not Expired | B28: Not Expire Total | D28: 4020 | E28: 42152.941 | F28: =E28/$E$29 -> 0.98662589
A29: Not Expired Total | D29: 4098 | E29: 42724.341
A30: (blank) | B30: (blank) | C30: (blank)
A31: (blank) | B31: (blank) Total
A32: (blank) Total
A33: Grand Total | D33: 4182 | E33: 43875.071
